<mujoco model="hjarm_golden">
  <compiler angle="radian"/>

  <asset>
    <mesh name="base_link" file="base_link.STL"/>
    <mesh name="Link1" file="Link1.STL"/>
    <mesh name="Link2" file="Link2.STL"/>
    <mesh name="Link3" file="Link3.STL"/>
    <mesh name="Link4" file="Link4.STL"/>
    <mesh name="Link5" file="Link5.STL"/>
    <mesh name="Link6" file="Link6.STL"/>
  </asset>

  <worldbody>
    <geom pos="0 0 0.1" quat="1 0 0 0" type="mesh" rgba="0.75294 0.75294 0.75294 1" mesh="base_link"/>
    <body name="Link1" pos="0 0 0.1" quat="0.499998 0.5 0.5 -0.500002">
      <inertial pos="-0.074266 0.011815 3.0696e-06" quat="0.711076 0.00637537 0.00655175 0.703056" mass="0.73371" diaginertia="0.000804618 0.000584711 0.000468341"/>
      <joint name="joint1" pos="0 0 0" axis="-1 0 0" range="-3.14 3.14" actuatorfrcrange="-50 50"/>
      <geom type="mesh" rgba="0.75294 0.75294 0.75294 1" mesh="Link1"/>
      <body name="Link2" pos="-0.0872 -0.0225 0">
        <inertial pos="-0.16698 -0.011966 -0.17283" quat="0.654713 0.263291 0.266308 0.656588" mass="0.70058" diaginertia="0.00124952 0.000989109 0.000305857"/>
        <joint name="joint2" pos="0 0 0" axis="0 -1 0" range="-2.53 0" actuatorfrcrange="-50 50"/>
        <geom type="mesh" rgba="0.75294 0.75294 0.75294 1" mesh="Link2"/>
        <body name="Link3" pos="-0.23142 0.0336 -0.23951" quat="0.410621 -0.575664 0.575666 -0.410622">
          <inertial pos="0.0044216 -0.052434 1.1034e-05" quat="0.70699 0.707213 0.00362605 -0.000709703" mass="0.38094" diaginertia="0.000194731 0.000180779 0.000148099"/>
          <joint name="joint3" pos="0 0 0" axis="-1 0 0" range="-4.06 0" actuatorfrcrange="-35 35"/>
          <geom type="mesh" rgba="0.75294 0.75294 0.75294 1" mesh="Link3"/>
          <body name="Link4" pos="0 -0.1294 0" quat="0.499998 -0.5 -0.500002 0.5">
            <inertial pos="-0.072787 0.00059635 1.3776e-05" quat="0.0225005 0.696658 -0.0295269 0.716442" mass="0.33896" diaginertia="0.000350719 0.000313539 0.000134342"/>
            <joint name="joint4" pos="0 0 0" axis="-1 0 0" range="-3.14 3.14" actuatorfrcrange="-15 15"/>
            <geom type="mesh" rgba="1 1 1 1" mesh="Link4"/>
            <body name="Link5" pos="-0.17375 0.018 0" quat="0.0505124 0.705299 -0.0505126 0.705302">
              <inertial pos="0.0014631 -2.4696e-05 4.1757e-10" quat="0.5 0.5 0.5 0.5" mass="0.030251" diaginertia="3.4415e-06 3.1278e-06 2.4728e-06"/>
              <joint name="joint5" pos="0 0 0" axis="1 0 0" range="0 2.55" actuatorfrcrange="-15 15"/>
              <geom type="mesh" rgba="0.79608 0.82353 0.93725 1" mesh="Link5"/>
              <body name="Link6" quat="-2.59734e-06 0.707105 0.707108 -2.59735e-06">
                <inertial pos="0.022981 -1.1912e-09 4.4528e-09" mass="0.089817" diaginertia="6.7899e-05 3.7367e-05 3.7367e-05"/>
                <joint name="joint6" pos="0 0 0" axis="1 0 0" range="-3.14 3.14" actuatorfrcrange="-15 15"/>
                <geom quat="1.32679e-06 0 1 0" type="mesh" rgba="0.79608 0.82353 0.93725 1" mesh="Link6"/>
              </body>
            </body>
          </body>
        </body>
      </body>
    </body>
  </worldbody>
</mujoco>
